[2024-09-10T02:50:10.992+0000] {taskinstance.py:1159} INFO - Dependencies all met for dep_context=non-requeueable deps ti=<TaskInstance: postgres_to_csv_dag.extract_postgres_to_csv manual__2024-09-10T02:50:08.171754+00:00 [queued]>
[2024-09-10T02:50:11.001+0000] {taskinstance.py:1159} INFO - Dependencies all met for dep_context=requeueable deps ti=<TaskInstance: postgres_to_csv_dag.extract_postgres_to_csv manual__2024-09-10T02:50:08.171754+00:00 [queued]>
[2024-09-10T02:50:11.002+0000] {taskinstance.py:1361} INFO - Starting attempt 1 of 2
[2024-09-10T02:50:11.014+0000] {taskinstance.py:1382} INFO - Executing <Task(PythonOperator): extract_postgres_to_csv> on 2024-09-10 02:50:08.171754+00:00
[2024-09-10T02:50:11.029+0000] {standard_task_runner.py:57} INFO - Started process 567 to run task
[2024-09-10T02:50:11.034+0000] {standard_task_runner.py:84} INFO - Running: ['***', 'tasks', 'run', 'postgres_to_csv_dag', 'extract_postgres_to_csv', 'manual__2024-09-10T02:50:08.171754+00:00', '--job-id', '66', '--raw', '--subdir', 'DAGS_FOLDER/postgres_to_csv_dag.py', '--cfg-path', '/tmp/tmpef_ti6zi']
[2024-09-10T02:50:11.039+0000] {standard_task_runner.py:85} INFO - Job 66: Subtask extract_postgres_to_csv
[2024-09-10T02:50:11.107+0000] {task_command.py:415} INFO - Running <TaskInstance: postgres_to_csv_dag.extract_postgres_to_csv manual__2024-09-10T02:50:08.171754+00:00 [running]> on host 604e2fe78157
[2024-09-10T02:50:11.609+0000] {taskinstance.py:1660} INFO - Exporting env vars: AIRFLOW_CTX_DAG_OWNER='fikri' AIRFLOW_CTX_DAG_ID='postgres_to_csv_dag' AIRFLOW_CTX_TASK_ID='extract_postgres_to_csv' AIRFLOW_CTX_EXECUTION_DATE='2024-09-10T02:50:08.171754+00:00' AIRFLOW_CTX_TRY_NUMBER='1' AIRFLOW_CTX_DAG_RUN_ID='manual__2024-09-10T02:50:08.171754+00:00'
[2024-09-10T02:50:11.647+0000] {base.py:73} INFO - Using connection ID 'local_***' for task execution.
[2024-09-10T02:50:11.761+0000] {logging_mixin.py:151} WARNING - /home/***/.local/lib/python3.8/site-packages/***/providers/common/sql/hooks/sql.py:219 UserWarning: pandas only supports SQLAlchemy connectable (engine/connection) or database string URI or sqlite3 DBAPI2 connection. Other DBAPI2 objects are not tested. Please consider using SQLAlchemy.
[2024-09-10T02:50:11.898+0000] {taskinstance.py:1943} ERROR - Task failed with exception
Traceback (most recent call last):
  File "/home/airflow/.local/lib/python3.8/site-packages/airflow/operators/python.py", line 192, in execute
    return_value = self.execute_callable()
  File "/home/airflow/.local/lib/python3.8/site-packages/airflow/operators/python.py", line 209, in execute_callable
    return self.python_callable(*self.op_args, **self.op_kwargs)
  File "/opt/airflow/dags/postgres_to_csv_dag.py", line 19, in postgres_to_csv
    df.to_csv('/opt/airflow/data/telecom_output_file.csv', index=False)
  File "/home/airflow/.local/lib/python3.8/site-packages/pandas/core/generic.py", line 3772, in to_csv
    return DataFrameRenderer(formatter).to_csv(
  File "/home/airflow/.local/lib/python3.8/site-packages/pandas/io/formats/format.py", line 1186, in to_csv
    csv_formatter.save()
  File "/home/airflow/.local/lib/python3.8/site-packages/pandas/io/formats/csvs.py", line 240, in save
    with get_handle(
  File "/home/airflow/.local/lib/python3.8/site-packages/pandas/io/common.py", line 737, in get_handle
    check_parent_directory(str(handle))
  File "/home/airflow/.local/lib/python3.8/site-packages/pandas/io/common.py", line 600, in check_parent_directory
    raise OSError(rf"Cannot save file into a non-existent directory: '{parent}'")
OSError: Cannot save file into a non-existent directory: '/opt/***/data'
[2024-09-10T02:50:11.931+0000] {taskinstance.py:1400} INFO - Marking task as UP_FOR_RETRY. dag_id=***_to_csv_dag, task_id=extract_***_to_csv, execution_date=20240910T025008, start_date=20240910T025010, end_date=20240910T025011
[2024-09-10T02:50:11.943+0000] {standard_task_runner.py:104} ERROR - Failed to execute job 66 for task extract_***_to_csv (Cannot save file into a non-existent directory: '/opt/***/data'; 567)
[2024-09-10T02:50:12.012+0000] {local_task_job_runner.py:228} INFO - Task exited with return code 1
[2024-09-10T02:50:12.046+0000] {taskinstance.py:2784} INFO - 0 downstream tasks scheduled from follow-on schedule check
