[2024-09-10T01:02:59.274+0000] {logging_mixin.py:151} WARNING - /home/***/.local/lib/python3.8/site-packages/***/utils/sqlalchemy.py:124 DeprecationWarning: The sql_alchemy_conn option in [core] has been moved to the sql_alchemy_conn option in [database] - the old setting has been used, but please update your config.
[2024-09-10T01:02:59.292+0000] {taskinstance.py:1159} INFO - Dependencies all met for dep_context=non-requeueable deps ti=<TaskInstance: postgres_to_csv_dag.extract_postgres_to_csv scheduled__2024-09-09T00:00:00+00:00 [queued]>
[2024-09-10T01:02:59.301+0000] {taskinstance.py:1159} INFO - Dependencies all met for dep_context=requeueable deps ti=<TaskInstance: postgres_to_csv_dag.extract_postgres_to_csv scheduled__2024-09-09T00:00:00+00:00 [queued]>
[2024-09-10T01:02:59.302+0000] {taskinstance.py:1361} INFO - Starting attempt 2 of 3
[2024-09-10T01:02:59.315+0000] {taskinstance.py:1382} INFO - Executing <Task(PythonOperator): extract_postgres_to_csv> on 2024-09-09 00:00:00+00:00
[2024-09-10T01:02:59.329+0000] {standard_task_runner.py:57} INFO - Started process 208 to run task
[2024-09-10T01:02:59.336+0000] {standard_task_runner.py:84} INFO - Running: ['***', 'tasks', 'run', 'postgres_to_csv_dag', 'extract_postgres_to_csv', 'scheduled__2024-09-09T00:00:00+00:00', '--job-id', '23', '--raw', '--subdir', 'DAGS_FOLDER/postgres_to_csv_dag.py', '--cfg-path', '/tmp/tmpwiwt6tjh']
[2024-09-10T01:02:59.342+0000] {standard_task_runner.py:85} INFO - Job 23: Subtask extract_postgres_to_csv
[2024-09-10T01:02:59.365+0000] {logging_mixin.py:151} WARNING - /home/***/.local/lib/python3.8/site-packages/***/settings.py:195 DeprecationWarning: The sql_alchemy_conn option in [core] has been moved to the sql_alchemy_conn option in [database] - the old setting has been used, but please update your config.
[2024-09-10T01:02:59.432+0000] {task_command.py:415} INFO - Running <TaskInstance: postgres_to_csv_dag.extract_postgres_to_csv scheduled__2024-09-09T00:00:00+00:00 [running]> on host 98d26deac256
[2024-09-10T01:02:59.449+0000] {logging_mixin.py:151} WARNING - /home/***/.local/lib/python3.8/site-packages/***/utils/sqlalchemy.py:124 DeprecationWarning: The sql_alchemy_conn option in [core] has been moved to the sql_alchemy_conn option in [database] - the old setting has been used, but please update your config.
[2024-09-10T01:02:59.545+0000] {taskinstance.py:1660} INFO - Exporting env vars: AIRFLOW_CTX_DAG_OWNER='fikri' AIRFLOW_CTX_DAG_ID='postgres_to_csv_dag' AIRFLOW_CTX_TASK_ID='extract_postgres_to_csv' AIRFLOW_CTX_EXECUTION_DATE='2024-09-09T00:00:00+00:00' AIRFLOW_CTX_TRY_NUMBER='2' AIRFLOW_CTX_DAG_RUN_ID='scheduled__2024-09-09T00:00:00+00:00'
[2024-09-10T01:02:59.854+0000] {base.py:73} INFO - Using connection ID 'local_***' for task execution.
[2024-09-10T01:02:59.860+0000] {taskinstance.py:1943} ERROR - Task failed with exception
Traceback (most recent call last):
  File "/home/airflow/.local/lib/python3.8/site-packages/airflow/operators/python.py", line 192, in execute
    return_value = self.execute_callable()
  File "/home/airflow/.local/lib/python3.8/site-packages/airflow/operators/python.py", line 209, in execute_callable
    return self.python_callable(*self.op_args, **self.op_kwargs)
  File "/opt/airflow/dags/postgres_to_csv_dag.py", line 16, in postgres_to_csv
    df = pg_hook.get_pandas_df(sql)
  File "/home/airflow/.local/lib/python3.8/site-packages/airflow/providers/common/sql/hooks/sql.py", line 218, in get_pandas_df
    with closing(self.get_conn()) as conn:
  File "/home/airflow/.local/lib/python3.8/site-packages/airflow/providers/postgres/hooks/postgres.py", line 154, in get_conn
    self.conn = psycopg2.connect(**conn_args)
  File "/home/airflow/.local/lib/python3.8/site-packages/psycopg2/__init__.py", line 122, in connect
    conn = _connect(dsn, connection_factory=connection_factory, **kwasync)
psycopg2.OperationalError: connection to server at "localhost" (127.0.0.1), port 5432 failed: Connection refused
	Is the server running on that host and accepting TCP/IP connections?
connection to server at "localhost" (::1), port 5432 failed: Cannot assign requested address
	Is the server running on that host and accepting TCP/IP connections?

[2024-09-10T01:02:59.879+0000] {taskinstance.py:1400} INFO - Marking task as UP_FOR_RETRY. dag_id=***_to_csv_dag, task_id=extract_***_to_csv, execution_date=20240909T000000, start_date=20240910T010259, end_date=20240910T010259
[2024-09-10T01:02:59.891+0000] {standard_task_runner.py:104} ERROR - Failed to execute job 23 for task extract_***_to_csv (connection to server at "localhost" (127.0.0.1), port 5432 failed: Connection refused
	Is the server running on that host and accepting TCP/IP connections?
connection to server at "localhost" (::1), port 5432 failed: Cannot assign requested address
	Is the server running on that host and accepting TCP/IP connections?
; 208)
[2024-09-10T01:02:59.941+0000] {local_task_job_runner.py:228} INFO - Task exited with return code 1
[2024-09-10T01:02:59.961+0000] {taskinstance.py:2784} INFO - 0 downstream tasks scheduled from follow-on schedule check
[2024-09-10T02:25:24.581+0000] {taskinstance.py:1159} INFO - Dependencies all met for dep_context=non-requeueable deps ti=<TaskInstance: postgres_to_csv_dag.extract_postgres_to_csv scheduled__2024-09-09T00:00:00+00:00 [queued]>
[2024-09-10T02:25:24.588+0000] {taskinstance.py:1159} INFO - Dependencies all met for dep_context=requeueable deps ti=<TaskInstance: postgres_to_csv_dag.extract_postgres_to_csv scheduled__2024-09-09T00:00:00+00:00 [queued]>
[2024-09-10T02:25:24.589+0000] {taskinstance.py:1361} INFO - Starting attempt 2 of 2
[2024-09-10T02:25:24.599+0000] {taskinstance.py:1382} INFO - Executing <Task(PythonOperator): extract_postgres_to_csv> on 2024-09-09 00:00:00+00:00
[2024-09-10T02:25:24.609+0000] {standard_task_runner.py:57} INFO - Started process 258 to run task
[2024-09-10T02:25:24.615+0000] {standard_task_runner.py:84} INFO - Running: ['***', 'tasks', 'run', 'postgres_to_csv_dag', 'extract_postgres_to_csv', 'scheduled__2024-09-09T00:00:00+00:00', '--job-id', '59', '--raw', '--subdir', 'DAGS_FOLDER/postgres_to_csv_dag.py', '--cfg-path', '/tmp/tmpq_xqumcb']
[2024-09-10T02:25:24.619+0000] {standard_task_runner.py:85} INFO - Job 59: Subtask extract_postgres_to_csv
[2024-09-10T02:25:24.679+0000] {task_command.py:415} INFO - Running <TaskInstance: postgres_to_csv_dag.extract_postgres_to_csv scheduled__2024-09-09T00:00:00+00:00 [running]> on host 604e2fe78157
[2024-09-10T02:25:24.755+0000] {taskinstance.py:1660} INFO - Exporting env vars: AIRFLOW_CTX_DAG_OWNER='fikri' AIRFLOW_CTX_DAG_ID='postgres_to_csv_dag' AIRFLOW_CTX_TASK_ID='extract_postgres_to_csv' AIRFLOW_CTX_EXECUTION_DATE='2024-09-09T00:00:00+00:00' AIRFLOW_CTX_TRY_NUMBER='2' AIRFLOW_CTX_DAG_RUN_ID='scheduled__2024-09-09T00:00:00+00:00'
[2024-09-10T02:25:24.922+0000] {base.py:73} INFO - Using connection ID 'local_***' for task execution.
[2024-09-10T02:25:24.924+0000] {taskinstance.py:1943} ERROR - Task failed with exception
Traceback (most recent call last):
  File "/home/airflow/.local/lib/python3.8/site-packages/airflow/operators/python.py", line 192, in execute
    return_value = self.execute_callable()
  File "/home/airflow/.local/lib/python3.8/site-packages/airflow/operators/python.py", line 209, in execute_callable
    return self.python_callable(*self.op_args, **self.op_kwargs)
  File "/opt/airflow/dags/postgres_to_csv_dag.py", line 16, in postgres_to_csv
    df = pg_hook.get_pandas_df(sql)
  File "/home/airflow/.local/lib/python3.8/site-packages/airflow/providers/common/sql/hooks/sql.py", line 218, in get_pandas_df
    with closing(self.get_conn()) as conn:
  File "/home/airflow/.local/lib/python3.8/site-packages/airflow/providers/postgres/hooks/postgres.py", line 154, in get_conn
    self.conn = psycopg2.connect(**conn_args)
  File "/home/airflow/.local/lib/python3.8/site-packages/psycopg2/__init__.py", line 122, in connect
    conn = _connect(dsn, connection_factory=connection_factory, **kwasync)
psycopg2.OperationalError: connection to server at "localhost" (127.0.0.1), port 5432 failed: Connection refused
	Is the server running on that host and accepting TCP/IP connections?
connection to server at "localhost" (::1), port 5432 failed: Cannot assign requested address
	Is the server running on that host and accepting TCP/IP connections?

[2024-09-10T02:25:24.938+0000] {taskinstance.py:1400} INFO - Marking task as FAILED. dag_id=***_to_csv_dag, task_id=extract_***_to_csv, execution_date=20240909T000000, start_date=20240910T022524, end_date=20240910T022524
[2024-09-10T02:25:24.947+0000] {standard_task_runner.py:104} ERROR - Failed to execute job 59 for task extract_***_to_csv (connection to server at "localhost" (127.0.0.1), port 5432 failed: Connection refused
	Is the server running on that host and accepting TCP/IP connections?
connection to server at "localhost" (::1), port 5432 failed: Cannot assign requested address
	Is the server running on that host and accepting TCP/IP connections?
; 258)
[2024-09-10T02:25:25.007+0000] {local_task_job_runner.py:228} INFO - Task exited with return code 1
[2024-09-10T02:25:25.026+0000] {taskinstance.py:2784} INFO - 0 downstream tasks scheduled from follow-on schedule check
