[2024-09-10T01:42:01.605+0000] {taskinstance.py:1159} INFO - Dependencies all met for dep_context=non-requeueable deps ti=<TaskInstance: postgres_to_csv_dag.extract_postgres_to_csv manual__2024-09-10T01:39:43.773129+00:00 [queued]>
[2024-09-10T01:42:01.612+0000] {taskinstance.py:1159} INFO - Dependencies all met for dep_context=requeueable deps ti=<TaskInstance: postgres_to_csv_dag.extract_postgres_to_csv manual__2024-09-10T01:39:43.773129+00:00 [queued]>
[2024-09-10T01:42:01.613+0000] {taskinstance.py:1361} INFO - Starting attempt 2 of 3
[2024-09-10T01:42:01.625+0000] {taskinstance.py:1382} INFO - Executing <Task(PythonOperator): extract_postgres_to_csv> on 2024-09-10 01:39:43.773129+00:00
[2024-09-10T01:42:01.636+0000] {standard_task_runner.py:57} INFO - Started process 312 to run task
[2024-09-10T01:42:01.642+0000] {standard_task_runner.py:84} INFO - Running: ['***', 'tasks', 'run', 'postgres_to_csv_dag', 'extract_postgres_to_csv', 'manual__2024-09-10T01:39:43.773129+00:00', '--job-id', '42', '--raw', '--subdir', 'DAGS_FOLDER/postgres_to_csv_dag.py', '--cfg-path', '/tmp/tmp0bknp0y3']
[2024-09-10T01:42:01.647+0000] {standard_task_runner.py:85} INFO - Job 42: Subtask extract_postgres_to_csv
[2024-09-10T01:42:01.723+0000] {task_command.py:415} INFO - Running <TaskInstance: postgres_to_csv_dag.extract_postgres_to_csv manual__2024-09-10T01:39:43.773129+00:00 [running]> on host d619af89c3a2
[2024-09-10T01:42:01.821+0000] {taskinstance.py:1660} INFO - Exporting env vars: AIRFLOW_CTX_DAG_OWNER='fikri' AIRFLOW_CTX_DAG_ID='postgres_to_csv_dag' AIRFLOW_CTX_TASK_ID='extract_postgres_to_csv' AIRFLOW_CTX_EXECUTION_DATE='2024-09-10T01:39:43.773129+00:00' AIRFLOW_CTX_TRY_NUMBER='2' AIRFLOW_CTX_DAG_RUN_ID='manual__2024-09-10T01:39:43.773129+00:00'
[2024-09-10T01:42:02.058+0000] {base.py:73} INFO - Using connection ID 'local_postgres' for task execution.
[2024-09-10T01:42:02.090+0000] {logging_mixin.py:151} WARNING - /home/***/.local/lib/python3.8/site-packages/***/providers/common/sql/hooks/sql.py:219 UserWarning: pandas only supports SQLAlchemy connectable (engine/connection) or database string URI or sqlite3 DBAPI2 connection. Other DBAPI2 objects are not tested. Please consider using SQLAlchemy.
[2024-09-10T01:42:02.093+0000] {taskinstance.py:1943} ERROR - Task failed with exception
Traceback (most recent call last):
  File "/home/airflow/.local/lib/python3.8/site-packages/pandas/io/sql.py", line 2202, in execute
    cur.execute(sql, *args)
psycopg2.errors.UndefinedTable: relation "telecom_customer_churn_output" does not exist
LINE 1: SELECT * FROM telecom_customer_churn_output;
                      ^


The above exception was the direct cause of the following exception:

Traceback (most recent call last):
  File "/home/airflow/.local/lib/python3.8/site-packages/airflow/operators/python.py", line 192, in execute
    return_value = self.execute_callable()
  File "/home/airflow/.local/lib/python3.8/site-packages/airflow/operators/python.py", line 209, in execute_callable
    return self.python_callable(*self.op_args, **self.op_kwargs)
  File "/opt/airflow/dags/postgres_to_csv_dag.py", line 16, in postgres_to_csv
    df = pg_hook.get_pandas_df(sql)
  File "/home/airflow/.local/lib/python3.8/site-packages/airflow/providers/common/sql/hooks/sql.py", line 219, in get_pandas_df
    return psql.read_sql(sql, con=conn, params=parameters, **kwargs)
  File "/home/airflow/.local/lib/python3.8/site-packages/pandas/io/sql.py", line 635, in read_sql
    return pandas_sql.read_query(
  File "/home/airflow/.local/lib/python3.8/site-packages/pandas/io/sql.py", line 2266, in read_query
    cursor = self.execute(sql, params)
  File "/home/airflow/.local/lib/python3.8/site-packages/pandas/io/sql.py", line 2214, in execute
    raise ex from exc
pandas.errors.DatabaseError: Execution failed on sql 'SELECT * FROM telecom_customer_churn_output;': relation "telecom_customer_churn_output" does not exist
LINE 1: SELECT * FROM telecom_customer_churn_output;
                      ^

[2024-09-10T01:42:02.114+0000] {taskinstance.py:1400} INFO - Marking task as UP_FOR_RETRY. dag_id=postgres_to_csv_dag, task_id=extract_postgres_to_csv, execution_date=20240910T013943, start_date=20240910T014201, end_date=20240910T014202
[2024-09-10T01:42:02.126+0000] {standard_task_runner.py:104} ERROR - Failed to execute job 42 for task extract_postgres_to_csv (Execution failed on sql 'SELECT * FROM telecom_customer_churn_output;': relation "telecom_customer_churn_output" does not exist
LINE 1: SELECT * FROM telecom_customer_churn_output;
                      ^
; 312)
[2024-09-10T01:42:02.197+0000] {local_task_job_runner.py:228} INFO - Task exited with return code 1
[2024-09-10T01:42:02.230+0000] {taskinstance.py:2784} INFO - 0 downstream tasks scheduled from follow-on schedule check
